Workbook

Sheet LMS_Loan_Tape
A1: loan_id | B1: disbursement_date | C1: principal_amount | D1: interest_rate | E1: tenure_months | F1: product_type | G1: lender_name | H1: status | I1: total_interest_accrued | J1: processing_fee_collected | K1: disb_month
A2: LN-10001 | B2: 45739 | C2: 1990685 | D2: 13.17 | E2: 36 | F2: Personal Loan | G2: DMI | H2: Active | I2: 305868 | J2: 33318 | K2: =MONTH(B2) -> 3
A3: LN-10002 | B3: 45811 | C3: 472946 | D3: 16.22 | E3: 24 | F3: Business Loan | G3: Tata Capital | H3: Active | I3: 70319 | J3: 9347 | K3: =MONTH(B3) -> 6
A4: LN-10003 | B4: 45891 | C4: 1164468 | D4: 13.4 | E4: 60 | F4: Home Loan | G4: Piramal | H4: Active | I4: 117029 | J4: 12951 | K4: =MONTH(B4) -> 8
A5: LN-10004 | B5: 46078 | C5: 1287900 | D5: 9.09 | E5: 24 | F5: Personal Loan | G5: Northern Arc | H5: Active | I5: 19511 | J5: 24107 | K5: =MONTH(B5) -> 2
A6: LN-10005 | B6: 45744 | C6: 274729 | D6: 12.7 | E6: 48 | F6: Personal Loan | G6: Piramal | H6: Active | I6: 37798 | J6: 2801 | K6: =MONTH(B6) -> 3
A7: LN-10006 | B7: 45736 | C7: 2292520 | D7: 8.94 | E7: 24 | F7: Business Loan | G7: DMI | H7: Closed | I7: 239109 | J7: 45022 | K7: =MONTH(B7) -> 3
A8: LN-10007 | B8: 45949 | C8: 370948 | D8: 13.8 | E8: 36 | F8: Gold Loan | G8: Piramal | H8: Active | I8: 29861 | J8: 4583 | K8: =MONTH(B8) -> 10
A9: LN-10008 | B9: 45858 | C9: 2512975 | D9: 8.95 | E9: 48 | F9: Business Loan | G9: Tata Capital | H9: Active | I9: 187426 | J9: 28021 | K9: =MONTH(B9) -> 7
A10: LN-10009 | B10: 45959 | C10: 2171036 | D10: 9.58 | E10: 12 | F10: Business Loan | G10: Northern Arc | H10: Active | I10: 103992 | J10: 34379 | K10: =MONTH(B10) -> 10
A11: LN-10010 | B11: 45752 | C11: 1684888 | D11: 12.61 | E11: 48 | F11: Personal Loan | G11: Northern Arc | H11: Active | I11: 230169 | J11: 31790 | K11: =MONTH(B11) -> 4
A12: LN-10011 | B12: 45796 | C12: 2707996 | D12: 11.8 | E12: 24 | F12: Home Loan | G12: Tata Capital | H12: Active | I12: 319543 | J12: 44197 | K12: =MONTH(B12) -> 5
A13: LN-10012 | B13: 45915 | C13: 160641 | D13: 12.24 | E13: 60 | F13: Business Loan | G13: DMI | H13: Closed | I13: 13108 | J13: 3158 | K13: =MONTH(B13) -> 9
... A301: LN-10300 | B301: 45642 | C301: 2453490 | D301: 11.42 | E301: 48 | F301: Home Loan | G301: Northern Arc | H301: Active | I301: 396933 | J301: 40369 | K301: =MONTH(B301) -> 12

Sheet Actual_Revenue
A1: loan_id | B1: expected_interest_income | C1: expected_processing_fee | D1: actual_interest_received | E1: actual_fee_received | F1: variance_flag | G1: variance_reason
A2: LN-10001 | B2: 305868 | C2: 33318 | D2: 299750 | E2: 33318 | F2: NO
A3: LN-10002 | B3: 70319 | C3: 9347 | D3: 70754 | E3: 9347 | F3: YES | G3: System Error
A4: LN-10003 | B4: 117029 | C4: 12951 | D4: 117029 | E4: 12951 | F4: NO
A5: LN-10004 | B5: 19511 | C5: 24107 | D5: 19511 | E5: 24107 | F5: NO
A6: LN-10005 | B6: 37798 | C6: 2801 | D6: 37798 | E6: 2801 | F6: NO
A7: LN-10006 | B7: 239109 | C7: 45022 | D7: 239109 | E7: 45022 | F7: NO
A8: LN-10007 | B8: 29861 | C8: 4583 | D8: 29861 | E8: 4583 | F8: NO
A9: LN-10008 | B9: 187426 | C9: 28021 | D9: 112455 | E9: 28021 | F9: YES | G9: Partial Payment
A10: LN-10009 | B10: 103992 | C10: 34379 | D10: 103992 | E10: 34379 | F10: NO
A11: LN-10010 | B11: 230169 | C11: 31790 | D11: 230169 | E11: 31790 | F11: NO
A12: LN-10011 | B12: 319543 | C12: 44197 | D12: 335520 | E12: 44197 | F12: YES | G12: Rate Change
A13: LN-10012 | B13: 13108 | C13: 3158 | D13: 13108 | E13: 3158 | F13: NO
A14: LN-10013 | B14: 99978 | C14: 7766 | D14: 79982 | E14: 7766 | F14: YES | G14: Prepayment
A15: LN-10014 | B15: 24454 | C15: 11423 | D15: 24454 | E15: 11423 | F15: NO
A16: LN-10015 | B16: 214052 | C16: 18188 | D16: 214052 | E16: 18006 | F16: NO
A17: LN-10016 | B17: 39348 | C17: 50359 | D17: 39348 | E17: 50359 | F17: NO
A18: LN-10017 | B18: 123653 | C18: 22061 | D18: 123653 | E18: 22061 | F18: NO
A19: LN-10018 | B19: 250333 | C19: 28741 | D19: 245326 | E19: 28741 | F19: NO
A20: LN-10019 | B20: 4129 | C20: 6319 | D20: 4129 | E20: 6319 | F20: NO
A21: LN-10020 | B21: 85614 | C21: 6214 | D21: 85614 | E21: 6214 | F21: NO
A22: LN-10021 | B22: 142107 | C22: 15153 | D22: 142107 | E22: 15153 | F22: NO
A23: LN-10022 | B23: 234424 | C23: 46764 | D23: 234424 | E23: 46764 | F23: NO
A24: LN-10023 | B24: 127873 | C24: 34584 | D24: 127873 | E24: 34584 | F24: NO
A25: LN-10024 | B25: 12976 | C25: 2181 | D25: 12976 | E25: 2181 | F25: NO
A26: LN-10025 | B26: 191863 | C26: 42905 | D26: 191863 | E26: 42905 | F26: NO
A27: LN-10026 | B27: 95442 | C27: 46122 | D27: 100214 | E27: 46122 | F27: YES | G27: Rate Change
A28: LN-10027 | B28: 47945 | C28: 23778 | D28: 28767 | E28: 23778 | F28: YES | G28: Partial Payment
A29: LN-10028 | B29: 294286 | C29: 20065 | D29: 294286 | E29: 20065 | F29: NO
A30: LN-10029 | B30: 79494 | C30: 15919 | D30: 79494 | E30: 15919 | F30: NO
A31: LN-10030 | B31: 268974 | C31: 46733 | D31: 268974 | E31: 46733 | F31: NO
A32: LN-10031 | B32: 179880 | C32: 26239 | D32: 179880 | E32: 26239 | F32: NO
A33: LN-10032 | B33: 11157 | C33: 6020 | D33: 11157 | E33: 6020 | F33: NO
A34: LN-10033 | B34: 52973 | C34: 7560 | D34: 53324 | E34: 7560 | F34: YES | G34: System Error
A35: LN-10034 | B35: 343815 | C35: 25582 | D35: 343815 | E35: 25582 | F35: NO
A36: LN-10035 | B36: 185332 | C36: 39414 | D36: 185332 | E36: 39414 | F36: NO
A37: LN-10036 | B37: 36630 | C37: 3817 | D37: 36630 | E37: 3817 | F37: NO
A38: LN-10037 | B38: 5410 | C38: 3526 | D38: 5410 | E38: 3490 | F38: NO
A39: LN-10038 | B39: 26305 | C39: 7083 | D39: 26305 | E39: 7083 | F39: NO
A40: LN-10039 | B40: 209421 | C40: 24678 | D40: 209421 | E40: 24678 | F40: NO
...

Sheet Reconciliation
A1: loan_id | B1: Expected Interest | C1: Actual Interest | D1: Interest Variance | E1: Variance % | F1: Expected Fee | G1: Actual Fee | H1: Fee Variance | I1: Status | J1: Reason
A2: =LMS_Loan_Tape!A2 -> LN-10001 | B2: =VLOOKUP(A2,Actual_Revenue!A:G,2,FALSE) -> 305868 | C2: =VLOOKUP(A2,Actual_Revenue!A:G,4,FALSE) -> 299750 | D2: =B2-C2 -> 6118 | E2: =(D2/B2) -> 0.020002092 | F2: =VLOOKUP(A2,Actual_Revenue!A:G,3,false) -> 33318 | G2: =VLOOKUP(A2,Actual_Revenue!A:G,5,false) -> 33318 | H2: =F2-G2 -> 0 | I2: =IF(AND(D2=0, H2=0),"MATCHED","EXCEPTION") -> EXCEPTION | J2: =VLOOKUP(A2,Actual_Revenue!A:G,7,false) | L2: Summary
A3: =LMS_Loan_Tape!A3 -> LN-10002 | B3: =VLOOKUP(A3,Actual_Revenue!A:G,2,FALSE) -> 70319 | C3: =VLOOKUP(A3,Actual_Revenue!A:G,4,FALSE) -> 70754 | D3: =B3-C3 -> -435 | E3: =(D3/B3) -> -0.0061860948 | F3: =VLOOKUP(A3,Actual_Revenue!A:G,3,false) -> 9347 | G3: =VLOOKUP(A3,Actual_Revenue!A:G,5,false) -> 9347 | H3: =F3-G3 -> 0 | I3: =IF(AND(D3=0, H3=0),"MATCHED","EXCEPTION") -> EXCEPTION | J3: =VLOOKUP(A3,Actual_Revenue!A:G,7,false) -> System Error | L3: Total Expected Revenue | M3: Total Actual Revenue | N3: Total Leakage | O3: Match Rate
A4: =LMS_Loan_Tape!A4 -> LN-10003 | B4: =VLOOKUP(A4,Actual_Revenue!A:G,2,FALSE) -> 117029 | C4: =VLOOKUP(A4,Actual_Revenue!A:G,4,FALSE) -> 117029 | D4: =B4-C4 -> 0 | E4: =(D4/B4) -> 0 | F4: =VLOOKUP(A4,Actual_Revenue!A:G,3,false) -> 12951 | G4: =VLOOKUP(A4,Actual_Revenue!A:G,5,false) -> 12951 | H4: =F4-G4 -> 0 | I4: =IF(AND(D4=0, H4=0),"MATCHED","EXCEPTION") -> MATCHED | J4: =VLOOKUP(A4,Actual_Revenue!A:G,7,false) | L4: =SUM(B:B) + SUM(F:F) -> 50685675 | M4: =SUM(C:C,G:G) -> 49630259 | N4: =L4-M4 -> 1055416 | O4: =COUNTIF(I:I, "MATCHED") / COUNTA(A:A) -> 0.71096346
A5: =LMS_Loan_Tape!A5 -> LN-10004 | B5: =VLOOKUP(A5,Actual_Revenue!A:G,2,FALSE) -> 19511 | C5: =VLOOKUP(A5,Actual_Revenue!A:G,4,FALSE) -> 19511 | D5: =B5-C5 -> 0 | E5: =(D5/B5) -> 0 | F5: =VLOOKUP(A5,Actual_Revenue!A:G,3,false) -> 24107 | G5: =VLOOKUP(A5,Actual_Revenue!A:G,5,false) -> 24107 | H5: =F5-G5 -> 0 | I5: =IF(AND(D5=0, H5=0),"MATCHED","EXCEPTION") -> MATCHED | J5: =VLOOKUP(A5,Actual_Revenue!A:G,7,false)
A6: =LMS_Loan_Tape!A6 -> LN-10005 | B6: =VLOOKUP(A6,Actual_Revenue!A:G,2,FALSE) -> 37798 | C6: =VLOOKUP(A6,Actual_Revenue!A:G,4,FALSE) -> 37798 | D6: =B6-C6 -> 0 | E6: =(D6/B6) -> 0 | F6: =VLOOKUP(A6,Actual_Revenue!A:G,3,false) -> 2801 | G6: =VLOOKUP(A6,Actual_Revenue!A:G,5,false) -> 2801 | H6: =F6-G6 -> 0 | I6: =IF(AND(D6=0, H6=0),"MATCHED","EXCEPTION") -> MATCHED | J6: =VLOOKUP(A6,Actual_Revenue!A:G,7,false)
A7: =LMS_Loan_Tape!A7 -> LN-10006 | B7: =VLOOKUP(A7,Actual_Revenue!A:G,2,FALSE) -> 239109 | C7: =VLOOKUP(A7,Actual_Revenue!A:G,4,FALSE) -> 239109 | D7: =B7-C7 -> 0 | E7: =(D7/B7) -> 0 | F7: =VLOOKUP(A7,Actual_Revenue!A:G,3,false) -> 45022 | G7: =VLOOKUP(A7,Actual_Revenue!A:G,5,false) -> 45022 | H7: =F7-G7 -> 0 | I7: =IF(AND(D7=0, H7=0),"MATCHED","EXCEPTION") -> MATCHED | J7: =VLOOKUP(A7,Actual_Revenue!A:G,7,false)
A8: =LMS_Loan_Tape!A8 -> LN-10007 | B8: =VLOOKUP(A8,Actual_Revenue!A:G,2,FALSE) -> 29861 | C8: =VLOOKUP(A8,Actual_Revenue!A:G,4,FALSE) -> 29861 | D8: =B8-C8 -> 0 | E8: =(D8/B8) -> 0 | F8: =VLOOKUP(A8,Actual_Revenue!A:G,3,false) -> 4583 | G8: =VLOOKUP(A8,Actual_Revenue!A:G,5,false) -> 4583 | H8: =F8-G8 -> 0 | I8: =IF(AND(D8=0, H8=0),"MATCHED","EXCEPTION") -> MATCHED | J8: =VLOOKUP(A8,Actual_Revenue!A:G,7,false)
A9: =LMS_Loan_Tape!A9 -> LN-10008 | B9: =VLOOKUP(A9,Actual_Revenue!A:G,2,FALSE) -> 187426 | C9: =VLOOKUP(A9,Actual_Revenue!A:G,4,FALSE) -> 112455 | D9: =B9-C9 -> 74971 | E9: =(D9/B9) -> 0.4000032 | F9: =VLOOKUP(A9,Actual_Revenue!A:G,3,false) -> 28021 | G9: =VLOOKUP(A9,Actual_Revenue!A:G,5,false) -> 28021 | H9: =F9-G9 -> 0 | I9: =IF(AND(D9=0, H9=0),"MATCHED","EXCEPTION") -> EXCEPTION | J9: =VLOOKUP(A9,Actual_Revenue!A:G,7,false) -> Partial Payment
A10: =LMS_Loan_Tape!A10 -> LN-10009 | B10: =VLOOKUP(A10,Actual_Revenue!A:G,2,FALSE) -> 103992 | C10: =VLOOKUP(A10,Actual_Revenue!A:G,4,FALSE) -> 103992 | D10: =B10-C10 -> 0 | E10: =(D10/B10) -> 0 | F10: =VLOOKUP(A10,Actual_Revenue!A:G,3,false) -> 34379 | G10: =VLOOKUP(A10,Actual_Revenue!A:G,5,false) -> 34379 | H10: =F10-G10 -> 0 | I10: =IF(AND(D10=0, H10=0),"MATCHED","EXCEPTION") -> MATCHED | J10: =VLOOKUP(A10,Actual_Revenue!A:G,7,false)
A11: =LMS_Loan_Tape!A11 -> LN-10010 | B11: =VLOOKUP(A11,Actual_Revenue!A:G,2,FALSE) -> 230169 | C11: =VLOOKUP(A11,Actual_Revenue!A:G,4,FALSE) -> 230169 | D11: =B11-C11 -> 0 | E11: =(D11/B11) -> 0 | F11: =VLOOKUP(A11,Actual_Revenue!A:G,3,false) -> 31790 | G11: =VLOOKUP(A11,Actual_Revenue!A:G,5,false) -> 31790 | H11: =F11-G11 -> 0 | I11: =IF(AND(D11=0, H11=0),"MATCHED","EXCEPTION") -> MATCHED | J11: =VLOOKUP(A11,Actual_Revenue!A:G,7,false)
A12: =LMS_Loan_Tape!A12 -> LN-10011 | B12: =VLOOKUP(A12,Actual_Revenue!A:G,2,FALSE) -> 319543 | C12: =VLOOKUP(A12,Actual_Revenue!A:G,4,FALSE) -> 335520 | D12: =B12-C12 -> -15977 | E12: =(D12/B12) -> -0.049999531 | F12: =VLOOKUP(A12,Actual_Revenue!A:G,3,false) -> 44197 | G12: =VLOOKUP(A12,Actual_Revenue!A:G,5,false) -> 44197 | H12: =F12-G12 -> 0 | I12: =IF(AND(D12=0, H12=0),"MATCHED","EXCEPTION") -> EXCEPTION | J12: =VLOOKUP(A12,Actual_Revenue!A:G,7,false) -> Rate Change
A13: =LMS_Loan_Tape!A13 -> LN-10012 | B13: =VLOOKUP(A13,Actual_Revenue!A:G,2,FALSE) -> 13108 | C13: =VLOOKUP(A13,Actual_Revenue!A:G,4,FALSE) -> 13108 | D13: =B13-C13 -> 0 | E13: =(D13/B13) -> 0 | F13: =VLOOKUP(A13,Actual_Revenue!A:G,3,false) -> 3158 | G13: =VLOOKUP(A13,Actual_Revenue!A:G,5,false) -> 3158 | H13: =F13-G13 -> 0 | I13: =IF(AND(D13=0, H13=0),"MATCHED","EXCEPTION") -> MATCHED | J13: =VLOOKUP(A13,Actual_Revenue!A:G,7,false)
A14: =LMS_Loan_Tape!A14 -> LN-10013 | B14: =VLOOKUP(A14,Actual_Revenue!A:G,2,FALSE) -> 99978 | C14: =VLOOKUP(A14,Actual_Revenue!A:G,4,FALSE) -> 79982 | D14: =B14-C14 -> 19996 | E14: =(D14/B14) -> 0.200004 | F14: =VLOOKUP(A14,Actual_Revenue!A:G,3,false) -> 7766 | G14: =VLOOKUP(A14,Actual_Revenue!A:G,5,false) -> 7766 | H14: =F14-G14 -> 0 | I14: =IF(AND(D14=0, H14=0),"MATCHED","EXCEPTION") -> EXCEPTION | J14: =VLOOKUP(A14,Actual_Revenue!A:G,7,false) -> Prepayment
A15: =LMS_Loan_Tape!A15 -> LN-10014 | B15: =VLOOKUP(A15,Actual_Revenue!A:G,2,FALSE) -> 24454 | C15: =VLOOKUP(A15,Actual_Revenue!A:G,4,FALSE) -> 24454 | D15: =B15-C15 -> 0 | E15: =(D15/B15) -> 0 | F15: =VLOOKUP(A15,Actual_Revenue!A:G,3,false) -> 11423 | G15: =VLOOKUP(A15,Actual_Revenue!A:G,5,false) -> 11423 | H15: =F15-G15 -> 0 | I15: =IF(AND(D15=0, H15=0),"MATCHED","EXCEPTION") -> MATCHED | J15: =VLOOKUP(A15,Actual_Revenue!A:G,7,false)
A16: =LMS_Loan_Tape!A16 -> LN-10015 | B16: =VLOOKUP(A16,Actual_Revenue!A:G,2,FALSE) -> 214052 | C16: =VLOOKUP(A16,Actual_Revenue!A:G,4,FALSE) -> 214052 | D16: =B16-C16 -> 0 | E16: =(D16/B16) -> 0 | F16: =VLOOKUP(A16,Actual_Revenue!A:G,3,false) -> 18188 | G16: =VLOOKUP(A16,Actual_Revenue!A:G,5,false) -> 18006 | H16: =F16-G16 -> 182 | I16: =IF(AND(D16=0, H16=0),"MATCHED","EXCEPTION") -> EXCEPTION | J16: =VLOOKUP(A16,Actual_Revenue!A:G,7,false)
... A301: =LMS_Loan_Tape!A301 -> LN-10300 | B301: =VLOOKUP(A301,Actual_Revenue!A:G,2,FALSE) -> 396933 | C301: =VLOOKUP(A301,Actual_Revenue!A:G,4,FALSE) -> 396933 | D301: =B301-C301 -> 0 | E301: =(D301/B301) -> 0 | F301: =VLOOKUP(A301,Actual_Revenue!A:G,3,false) -> 40369 | G301: =VLOOKUP(A301,Actual_Revenue!A:G,5,false) -> 40369 | H301: =F301-G301 -> 0 | I301: =IF(AND(D301=0, H301=0),"MATCHED","EXCEPTION") -> MATCHED | J301: =VLOOKUP(A301,Actual_Revenue!A:G,7,false)
A302: =LMS_Loan_Tape!A302
A303: =LMS_Loan_Tape!A303
A304: =LMS_Loan_Tape!A304
A305: =LMS_Loan_Tape!A305
A306: =LMS_Loan_Tape!A306
A307: =LMS_Loan_Tape!A307
A308: =LMS_Loan_Tape!A308

Sheet Exception_Report
A1: loan_id | B1: Expected Interest | C1: Actual Interest | D1: Interest Variance | E1: Variance % | F1: Expected Fee | G1: Actual Fee | H1: Fee Variance | I1: Status | J1: Reason | K1: Action Required | L1: Lender | M1: Total variance | N1: product_type | O1: month | P1: Reason | Q1: Count of Loans | R1: Total Variance
A2: =IFERROR(__xludf.DUMMYFUNCTION("FILTER(Reconciliation!A:J, Reconciliation!I:I = ""EXCEPTION"")"),"LN-10001") -> LN-10001 | B2: =IFERROR(__xludf.DUMMYFUNCTION("""COMPUTED_VALUE"""),305868.0) -> 305868 | C2: =IFERROR(__xludf.DUMMYFUNCTION("""COMPUTED_VALUE"""),299750.0) -> 299750 | D2: =IFERROR(__xludf.DUMMYFUNCTION("""COMPUTED_VALUE"""),6118.0) -> 6118 | E2: =IFERROR(__xludf.DUMMYFUNCTION("""COMPUTED_VALUE"""),0.02000209240587443) -> 0.020002092 | F2: =IFERROR(__xludf.DUMMYFUNCTION("""COMPUTED_VALUE"""),33318.0) -> 33318 | G2: =IFERROR(__xludf.DUMMYFUNCTION("""COMPUTED_VALUE"""),33318.0) -> 33318 | H2: =IFERROR(__xludf.DUMMYFUNCTION("""COMPUTED_VALUE"""),0.0) -> 0 | I2: =IFERROR(__xludf.DUMMYFUNCTION("""COMPUTED_VALUE"""),"EXCEPTION") -> EXCEPTION | K2: =IFS(J2="Prepayment", "Update schedule, recalculate interest",J2="System Error", "Escalate to tech team",J2="Waiver Applied", "Verify approval, update ledger",J2="Partial Payment", "Contact customer for balance",J2="Rate Change", "Update loan agreement",J2="", "" ) | L2: =VLOOKUP(A2,LMS_Loan_Tape!A:Z,7,FALSE) -> DMI | M2: =D2+H2 -> 6118 | N2: =VLOOKUP(A2,LMS_Loan_Tape!A:Z,6,FALSE) -> Personal Loan | O2: =VLOOKUP(A2, LMS_Loan_Tape!A1:Z1000,11,false) -> 3 | P2: System Error | Q2: =COUNTIF(J:J,"System Error") -> 12 | R2: =SUMIF(J:J,"System Error",D:D)+SUMIF(J:J,"System Error",H:H) -> -6730
A3: =IFERROR(__xludf.DUMMYFUNCTION("""COMPUTED_VALUE"""),"LN-10002") -> LN-10002 | B3: =IFERROR(__xludf.DUMMYFUNCTION("""COMPUTED_VALUE"""),70319.0) -> 70319 | C3: =IFERROR(__xludf.DUMMYFUNCTION("""COMPUTED_VALUE"""),70754.0) -> 70754 | D3: =IFERROR(__xludf.DUMMYFUNCTION("""COMPUTED_VALUE"""),-435.0) -> -435 | E3: =IFERROR(__xludf.DUMMYFUNCTION("""COMPUTED_VALUE"""),-0.006186094796569917) -> -0.0061860948 | F3: =IFERROR(__xludf.DUMMYFUNCTION("""COMPUTED_VALUE"""),9347.0) -> 9347 | G3: =IFERROR(__xludf.DUMMYFUNCTION("""COMPUTED_VALUE"""),9347.0) -> 9347 | H3: =IFERROR(__xludf.DUMMYFUNCTION("""COMPUTED_VALUE"""),0.0) -> 0 | I3: =IFERROR(__xludf.DUMMYFUNCTION("""COMPUTED_VALUE"""),"EXCEPTION") -> EXCEPTION | J3: =IFERROR(__xludf.DUMMYFUNCTION("""COMPUTED_VALUE"""),"System Error") -> System Error | K3: =IFS(J3="Prepayment", "Update schedule, recalculate interest",J3="System Error", "Escalate to tech team",J3="Waiver Applied", "Verify approval, update ledger",J3="Partial Payment", "Contact customer for balance",J3="Rate Change", "Update loan agreement",J3="", "" ) -> Escalate to tech team | L3: =VLOOKUP(A3,LMS_Loan_Tape!A:Z,7,FALSE) -> Tata Capital | M3: =D3+H3 -> -435 | N3: =VLOOKUP(A3,LMS_Loan_Tape!A:Z,6,FALSE) -> Business Loan | O3: =VLOOKUP(A3, LMS_Loan_Tape!A2:Z1001,11,false) -> 6 | P3: Partial Payment | Q3: =COUNTIF(J:J,"Partial Payment") -> 12 | R3: =SUMIF(J:J,"Partial Payment",D:D)+SUMIF(J:J,"Partial Payment",H:H) -> 856935
A4: =IFERROR(__xludf.DUMMYFUNCTION("""COMPUTED_VALUE"""),"LN-10008") -> LN-10008 | B4: =IFERROR(__xludf.DUMMYFUNCTION("""COMPUTED_VALUE"""),187426.0) -> 187426 | C4: =IFERROR(__xludf.DUMMYFUNCTION("""COMPUTED_VALUE"""),112455.0) -> 112455 | D4: =IFERROR(__xludf.DUMMYFUNCTION("""COMPUTED_VALUE"""),74971.0) -> 74971 | E4: =IFERROR(__xludf.DUMMYFUNCTION("""COMPUTED_VALUE"""),0.400003201263432) -> 0.4000032 | F4: =IFERROR(__xludf.DUMMYFUNCTION("""COMPUTED_VALUE"""),28021.0) -> 28021 | G4: =IFERROR(__xludf.DUMMYFUNCTION("""COMPUTED_VALUE"""),28021.0) -> 28021 | H4: =IFERROR(__xludf.DUMMYFUNCTION("""COMPUTED_VALUE"""),0.0) -> 0 | I4: =IFERROR(__xludf.DUMMYFUNCTION("""COMPUTED_VALUE"""),"EXCEPTION") -> EXCEPTION | J4: =IFERROR(__xludf.DUMMYFUNCTION("""COMPUTED_VALUE"""),"Partial Payment") -> Partial Payment | K4: =IFS(J4="Prepayment", "Update schedule, recalculate interest",J4="System Error", "Escalate to tech team",J4="Waiver Applied", "Verify approval, update ledger",J4="Partial Payment", "Contact customer for balance",J4="Rate Change", "Update loan agreement",J4="", "" ) -> Contact customer for balance | L4: =VLOOKUP(A4,LMS_Loan_Tape!A:Z,7,FALSE) -> Tata Capital | M4: =D4+H4 -> 74971 | N4: =VLOOKUP(A4,LMS_Loan_Tape!A:Z,6,FALSE) -> Business Loan | O4: =VLOOKUP(A4, LMS_Loan_Tape!A3:Z1002,11,false) -> 7 | P4: Rate Change | Q4: =COUNTIF(J:J,"Rate Change") -> 9 | R4: =SUMIF(J:J,"Rate Change",D:D)+SUMIF(J:J,"Rate Change",H:H) -> -57604
A5: =IFERROR(__xludf.DUMMYFUNCTION("""COMPUTED_VALUE"""),"LN-10011") -> LN-10011 | B5: =IFERROR(__xludf.DUMMYFUNCTION("""COMPUTED_VALUE"""),319543.0) -> 319543 | C5: =IFERROR(__xludf.DUMMYFUNCTION("""COMPUTED_VALUE"""),335520.0) -> 335520 | D5: =IFERROR(__xludf.DUMMYFUNCTION("""COMPUTED_VALUE"""),-15977.0) -> -15977 | E5: =IFERROR(__xludf.DUMMYFUNCTION("""COMPUTED_VALUE"""),-0.04999953057960901) -> -0.049999531 | F5: =IFERROR(__xludf.DUMMYFUNCTION("""COMPUTED_VALUE"""),44197.0) -> 44197 | G5: =IFERROR(__xludf.DUMMYFUNCTION("""COMPUTED_VALUE"""),44197.0) -> 44197 | H5: =IFERROR(__xludf.DUMMYFUNCTION("""COMPUTED_VALUE"""),0.0) -> 0 | I5: =IFERROR(__xludf.DUMMYFUNCTION("""COMPUTED_VALUE"""),"EXCEPTION") -> EXCEPTION | J5: =IFERROR(__xludf.DUMMYFUNCTION("""COMPUTED_VALUE"""),"Rate Change") -> Rate Change | K5: =IFS(J5="Prepayment", "Update schedule, recalculate interest",J5="System Error", "Escalate to tech team",J5="Waiver Applied", "Verify approval, update ledger",J5="Partial Payment", "Contact customer for balance",J5="Rate Change", "Update loan agreement",J5="", "" ) -> Update loan agreement | L5: =VLOOKUP(A5,LMS_Loan_Tape!A:Z,7,FALSE) -> Tata Capital | M5: =D5+H5 -> -15977 | N5: =VLOOKUP(A5,LMS_Loan_Tape!A:Z,6,FALSE) -> Home Loan | O5: =VLOOKUP(A5, LMS_Loan_Tape!A4:Z1003,11,false) -> 5 | P5: Prepayment | Q5: =COUNTIF(J:J,"Prepayment") -> 4 | R5: =SUMIF(J:J,"Prepayment",D:D)+SUMIF(J:J,"Prepayment",H:H) -> 42022
A6: =IFERROR(__xludf.DUMMYFUNCTION("""COMPUTED_VALUE"""),"LN-10013") -> LN-10013 | B6: =IFERROR(__xludf.DUMMYFUNCTION("""COMPUTED_VALUE"""),99978.0) -> 99978 | C6: =IFERROR(__xludf.DUMMYFUNCTION("""COMPUTED_VALUE"""),79982.0) -> 79982 | D6: =IFERROR(__xludf.DUMMYFUNCTION("""COMPUTED_VALUE"""),19996.0) -> 19996 | E6: =IFERROR(__xludf.DUMMYFUNCTION("""COMPUTED_VALUE"""),0.20000400088019366) -> 0.200004 | F6: =IFERROR(__xludf.DUMMYFUNCTION("""COMPUTED_VALUE"""),7766.0) -> 7766 | G6: =IFERROR(__xludf.DUMMYFUNCTION("""COMPUTED_VALUE"""),7766.0) -> 7766 | H6: =IFERROR(__xludf.DUMMYFUNCTION("""COMPUTED_VALUE"""),0.0) -> 0 | I6: =IFERROR(__xludf.DUMMYFUNCTION("""COMPUTED_VALUE"""),"EXCEPTION") -> EXCEPTION | J6: =IFERROR(__xludf.DUMMYFUNCTION("""COMPUTED_VALUE"""),"Prepayment") -> Prepayment | K6: =IFS(J6="Prepayment", "Update schedule, recalculate interest",J6="System Error", "Escalate to tech team",J6="Waiver Applied", "Verify approval, update ledger",J6="Partial Payment", "Contact customer for balance",J6="Rate Change", "Update loan agreement",J6="", "" ) -> Update schedule, recalculate interest | L6: =VLOOKUP(A6,LMS_Loan_Tape!A:Z,7,FALSE) -> DMI | M6: =D6+H6 -> 19996 | N6: =VLOOKUP(A6,LMS_Loan_Tape!A:Z,6,FALSE) -> Gold Loan | O6: =VLOOKUP(A6, LMS_Loan_Tape!A5:Z1004,11,false) -> 3 | P6: Waiver Applied | Q6: =COUNTIF(J:J,"Waiver Applied") -> 9 | R6: =SUMIF(J:J,"Waiver Applied",D:D)+SUMIF(J:J,"Waiver Applied",H:H) -> 162015
A7: =IFERROR(__xludf.DUMMYFUNCTION("""COMPUTED_VALUE"""),"LN-10015") -> LN-10015 | B7: =IFERROR(__xludf.DUMMYFUNCTION("""COMPUTED_VALUE"""),214052.0) -> 214052 | C7: =IFERROR(__xludf.DUMMYFUNCTION("""COMPUTED_VALUE"""),214052.0) -> 214052 | D7: =IFERROR(__xludf.DUMMYFUNCTION("""COMPUTED_VALUE"""),0.0) -> 0 | E7: =IFERROR(__xludf.DUMMYFUNCTION("""COMPUTED_VALUE"""),0.0) -> 0 | F7: =IFERROR(__xludf.DUMMYFUNCTION("""COMPUTED_VALUE"""),18188.0) -> 18188 | G7: =IFERROR(__xludf.DUMMYFUNCTION("""COMPUTED_VALUE"""),18006.0) -> 18006 | H7: =IFERROR(__xludf.DUMMYFUNCTION("""COMPUTED_VALUE"""),182.0) -> 182 | I7: =IFERROR(__xludf.DUMMYFUNCTION("""COMPUTED_VALUE"""),"EXCEPTION") -> EXCEPTION | K7: =IFS(J7="Prepayment", "Update schedule, recalculate interest",J7="System Error", "Escalate to tech team",J7="Waiver Applied", "Verify approval, update ledger",J7="Partial Payment", "Contact customer for balance",J7="Rate Change", "Update loan agreement",J7="", "" ) | L7: =VLOOKUP(A7,LMS_Loan_Tape!A:Z,7,FALSE) -> Piramal | M7: =D7+H7 -> 182 | N7: =VLOOKUP(A7,LMS_Loan_Tape!A:Z,6,FALSE) -> Gold Loan | O7: =VLOOKUP(A7, LMS_Loan_Tape!A6:Z1005,11,false) -> 4
A8: =IFERROR(__xludf.DUMMYFUNCTION("""COMPUTED_VALUE"""),"LN-10018") -> LN-10018 | B8: =IFERROR(__xludf.DUMMYFUNCTION("""COMPUTED_VALUE"""),250333.0) -> 250333 | C8: =IFERROR(__xludf.DUMMYFUNCTION("""COMPUTED_VALUE"""),245326.0) -> 245326 | D8: =IFERROR(__xludf.DUMMYFUNCTION("""COMPUTED_VALUE"""),5007.0) -> 5007 | E8: =IFERROR(__xludf.DUMMYFUNCTION("""COMPUTED_VALUE"""),0.020001358190889735) -> 0.020001358 | F8: =IFERROR(__xludf.DUMMYFUNCTION("""COMPUTED_VALUE"""),28741.0) -> 28741 | G8: =IFERROR(__xludf.DUMMYFUNCTION("""COMPUTED_VALUE"""),28741.0) -> 28741 | H8: =IFERROR(__xludf.DUMMYFUNCTION("""COMPUTED_VALUE"""),0.0) -> 0 | I8: =IFERROR(__xludf.DUMMYFUNCTION("""COMPUTED_VALUE"""),"EXCEPTION") -> EXCEPTION | K8: =IFS(J8="Prepayment", "Update schedule, recalculate interest",J8="System Error", "Escalate to tech team",J8="Waiver Applied", "Verify approval, update ledger",J8="Partial Payment", "Contact customer for balance",J8="Rate Change", "Update loan agreement",J8="", "" ) | L8: =VLOOKUP(A8,LMS_Loan_Tape!A:Z,7,FALSE) -> Northern Arc | M8: =D8+H8 -> 5007 | N8: =VLOOKUP(A8,LMS_Loan_Tape!A:Z,6,FALSE) -> Personal Loan | O8: =VLOOKUP(A8, LMS_Loan_Tape!A7:Z1006,11,false) -> 5
A9: =IFERROR(__xludf.DUMMYFUNCTION("""COMPUTED_VALUE"""),"LN-10026") -> LN-10026 | B9: =IFERROR(__xludf.DUMMYFUNCTION("""COMPUTED_VALUE"""),95442.0) -> 95442 | C9: =IFERROR(__xludf.DUMMYFUNCTION("""COMPUTED_VALUE"""),100214.0) -> 100214 | D9: =IFERROR(__xludf.DUMMYFUNCTION("""COMPUTED_VALUE"""),-4772.0) -> -4772 | E9: =IFERROR(__xludf.DUMMYFUNCTION("""COMPUTED_VALUE"""),-0.049998952243247206) -> -0.049998952 | F9: =IFERROR(__xludf.DUMMYFUNCTION("""COMPUTED_VALUE"""),46122.0) -> 46122 | G9: =IFERROR(__xludf.DUMMYFUNCTION("""COMPUTED_VALUE"""),46122.0) -> 46122 | H9: =IFERROR(__xludf.DUMMYFUNCTION("""COMPUTED_VALUE"""),0.0) -> 0 | I9: =IFERROR(__xludf.DUMMYFUNCTION("""COMPUTED_VALUE"""),"EXCEPTION") -> EXCEPTION | J9: =IFERROR(__xludf.DUMMYFUNCTION("""COMPUTED_VALUE"""),"Rate Change") -> Rate Change | K9: =IFS(J9="Prepayment", "Update schedule, recalculate interest",J9="System Error", "Escalate to tech team",J9="Waiver Applied", "Verify approval, update ledger",J9="Partial Payment", "Contact customer for balance",J9="Rate Change", "Update loan agreement",J9="", "" ) -> Update loan agreement | L9: =VLOOKUP(A9,LMS_Loan_Tape!A:Z,7,FALSE) -> DMI | M9: =D9+H9 -> -4772 | N9: =VLOOKUP(A9,LMS_Loan_Tape!A:Z,6,FALSE) -> Gold Loan | O9: =VLOOKUP(A9, LMS_Loan_Tape!A8:Z1007,11,false) -> 1
A10: =IFERROR(__xludf.DUMMYFUNCTION("""COMPUTED_VALUE"""),"LN-10027") -> LN-10027 | B10: =IFERROR(__xludf.DUMMYFUNCTION("""COMPUTED_VALUE"""),47945.0) -> 47945 | C10: =IFERROR(__xludf.DUMMYFUNCTION("""COMPUTED_VALUE"""),28767.0) -> 28767 | D10: =IFERROR(__xludf.DUMMYFUNCTION("""COMPUTED_VALUE"""),19178.0) -> 19178 | E10: =IFERROR(__xludf.DUMMYFUNCTION("""COMPUTED_VALUE"""),0.4) -> 0.4 | F10: =IFERROR(__xludf.DUMMYFUNCTION("""COMPUTED_VALUE"""),23778.0) -> 23778 | G10: =IFERROR(__xludf.DUMMYFUNCTION("""COMPUTED_VALUE"""),23778.0) -> 23778 | H10: =IFERROR(__xludf.DUMMYFUNCTION("""COMPUTED_VALUE"""),0.0) -> 0 | I10: =IFERROR(__xludf.DUMMYFUNCTION("""COMPUTED_VALUE"""),"EXCEPTION") -> EXCEPTION | J10: =IFERROR(__xludf.DUMMYFUNCTION("""COMPUTED_VALUE"""),"Partial Payment") -> Partial Payment | K10: =IFS(J10="Prepayment", "Update schedule, recalculate interest",J10="System Error", "Escalate to tech team",J10="Waiver Applied", "Verify approval, update ledger",J10="Partial Payment", "Contact customer for balance",J10="Rate Change", "Update loan agreement",J10="", "" ) -> Contact customer for balance | L10: =VLOOKUP(A10,LMS_Loan_Tape!A:Z,7,FALSE) -> Piramal | M10: =D10+H10 -> 19178 | N10: =VLOOKUP(A10,LMS_Loan_Tape!A:Z,6,FALSE) -> Business Loan | O10: =VLOOKUP(A10, LMS_Loan_Tape!A9:Z1008,11,false) -> 2
A11: =IFERROR(__xludf.DUMMYFUNCTION("""COMPUTED_VALUE"""),"LN-10033") -> LN-10033 | B11: =IFERROR(__xludf.DUMMYFUNCTION("""COMPUTED_VALUE"""),52973.0) -> 52973 | C11: =IFERROR(__xludf.DUMMYFUNCTION("""COMPUTED_VALUE"""),53324.0) -> 53324 | D11: =IFERROR(__xludf.DUMMYFUNCTION("""COMPUTED_VALUE"""),-351.0) -> -351 | E11: =IFERROR(__xludf.DUMMYFUNCTION("""COMPUTED_VALUE"""),-0.006626017027542333) -> -0.006626017 | F11: =IFERROR(__xludf.DUMMYFUNCTION("""COMPUTED_VALUE"""),7560.0) -> 7560 | G11: =IFERROR(__xludf.DUMMYFUNCTION("""COMPUTED_VALUE"""),7560.0) -> 7560 | H11: =IFERROR(__xludf.DUMMYFUNCTION("""COMPUTED_VALUE"""),0.0) -> 0 | I11: =IFERROR(__xludf.DUMMYFUNCTION("""COMPUTED_VALUE"""),"EXCEPTION") -> EXCEPTION | J11: =IFERROR(__xludf.DUMMYFUNCTION("""COMPUTED_VALUE"""),"System Error") -> System Error | K11: =IFS(J11="Prepayment", "Update schedule, recalculate interest",J11="System Error", "Escalate to tech team",J11="Waiver Applied", "Verify approval, update ledger",J11="Partial Payment", "Contact customer for balance",J11="Rate Change", "Update loan agreement",J11="", "" ) -> Escalate to tech team | L11: =VLOOKUP(A11,LMS_Loan_Tape!A:Z,7,FALSE) -> DMI | M11: =D11+H11 -> -351 | N11: =VLOOKUP(A11,LMS_Loan_Tape!A:Z,6,FALSE) -> Home Loan | O11: =VLOOKUP(A11, LMS_Loan_Tape!A10:Z1009,11,false) -> 4
A12: =IFERROR(__xludf.DUMMYFUNCTION("""COMPUTED_VALUE"""),"LN-10037") -> LN-10037 | B12: =IFERROR(__xludf.DUMMYFUNCTION("""COMPUTED_VALUE"""),5410.0) -> 5410 | C12: =IFERROR(__xludf.DUMMYFUNCTION("""COMPUTED_VALUE"""),5410.0) -> 5410 | D12: =IFERROR(__xludf.DUMMYFUNCTION("""COMPUTED_VALUE"""),0.0) -> 0 | E12: =IFERROR(__xludf.DUMMYFUNCTION("""COMPUTED_VALUE"""),0.0) -> 0 | F12: =IFERROR(__xludf.DUMMYFUNCTION("""COMPUTED_VALUE"""),3526.0) -> 3526 | G12: =IFERROR(__xludf.DUMMYFUNCTION("""COMPUTED_VALUE"""),3490.0) -> 3490 | H12: =IFERROR(__xludf.DUMMYFUNCTION("""COMPUTED_VALUE"""),36.0) -> 36 | I12: =IFERROR(__xludf.DUMMYFUNCTION("""COMPUTED_VALUE"""),"EXCEPTION") -> EXCEPTION | K12: =IFS(J12="Prepayment", "Update schedule, recalculate interest",J12="System Error", "Escalate to tech team",J12="Waiver Applied", "Verify approval, update ledger",J12="Partial Payment", "Contact customer for balance",J12="Rate Change", "Update loan agreement",J12="", "" ) | L12: =VLOOKUP(A12,LMS_Loan_Tape!A:Z,7,FALSE) -> Piramal | M12: =D12+H12 -> 36 | N12: =VLOOKUP(A12,LMS_Loan_Tape!A:Z,6,FALSE) -> Personal Loan | O12: =VLOOKUP(A12, LMS_Loan_Tape!A11:Z1010,11,false) -> 3
A13: =IFERROR(__xludf.DUMMYFUNCTION("""COMPUTED_VALUE"""),"LN-10040") -> LN-10040 | B13: =IFERROR(__xludf.DUMMYFUNCTION("""COMPUTED_VALUE"""),36428.0) -> 36428 | C13: =IFERROR(__xludf.DUMMYFUNCTION("""COMPUTED_VALUE"""),37193.0) -> 37193 | D13: =IFERROR(__xludf.DUMMYFUNCTION("""COMPUTED_VALUE"""),-765.0) -> -765 | E13: =IFERROR(__xludf.DUMMYFUNCTION("""COMPUTED_VALUE"""),-0.02100032941693203) -> -0.021000329 | F13: =IFERROR(__xludf.DUMMYFUNCTION("""COMPUTED_VALUE"""),45169.0) -> 45169 | G13: =IFERROR(__xludf.DUMMYFUNCTION("""COMPUTED_VALUE"""),45169.0) -> 45169 | H13: =IFERROR(__xludf.DUMMYFUNCTION("""COMPUTED_VALUE"""),0.0) -> 0 | I13: =IFERROR(__xludf.DUMMYFUNCTION("""COMPUTED_VALUE"""),"EXCEPTION") -> EXCEPTION | J13: =IFERROR(__xludf.DUMMYFUNCTION("""COMPUTED_VALUE"""),"System Error") -> System Error | K13: =IFS(J13="Prepayment", "Update schedule, recalculate interest",J13="System Error", "Escalate to tech team",J13="Waiver Applied", "Verify approval, update ledger",J13="Partial Payment", "Contact customer for balance",J13="Rate Change", "Update loan agreement",J13="", "" ) -> Escalate to tech team | L13: =VLOOKUP(A13,LMS_Loan_Tape!A:Z,7,FALSE) -> DMI | M13: =D13+H13 -> -765 | N13: =VLOOKUP(A13,LMS_Loan_Tape!A:Z,6,FALSE) -> Personal Loan | O13: =VLOOKUP(A13, LMS_Loan_Tape!A12:Z1011,11,false) -> 3
A14: =IFERROR(__xludf.DUMMYFUNCTION("""COMPUTED_VALUE"""),"LN-10044") -> LN-10044 | B14: =IFERROR(__xludf.DUMMYFUNCTION("""COMPUTED_VALUE"""),7409.0) -> 7409 | C14: =IFERROR(__xludf.DUMMYFUNCTION("""COMPUTED_VALUE"""),7409.0) -> 7409 | D14: =IFERROR(__xludf.DUMMYFUNCTION("""COMPUTED_VALUE"""),0.0) -> 0 | E14: =IFERROR(__xludf.DUMMYFUNCTION("""COMPUTED_VALUE"""),0.0) -> 0 | F14: =IFERROR(__xludf.DUMMYFUNCTION("""COMPUTED_VALUE"""),836.0) -> 836 | G14: =IFERROR(__xludf.DUMMYFUNCTION("""COMPUTED_VALUE"""),827.0) -> 827 | H14: =IFERROR(__xludf.DUMMYFUNCTION("""COMPUTED_VALUE"""),9.0) -> 9 | I14: =IFERROR(__xludf.DUMMYFUNCTION("""COMPUTED_VALUE"""),"EXCEPTION") -> EXCEPTION | K14: =IFS(J14="Prepayment", "Update schedule, recalculate interest",J14="System Error", "Escalate to tech team",J14="Waiver Applied", "Verify approval, update ledger",J14="Partial Payment", "Contact customer for balance",J14="Rate Change", "Update loan agreement",J14="", "" ) | L14: =VLOOKUP(A14,LMS_Loan_Tape!A:Z,7,FALSE) -> DMI | M14: =D14+H14 -> 9 | N14: =VLOOKUP(A14,LMS_Loan_Tape!A:Z,6,FALSE) -> Home Loan | O14: =VLOOKUP(A14, LMS_Loan_Tape!A13:Z1012,11,false) -> 1
A15: =IFERROR(__xludf.DUMMYFUNCTION("""COMPUTED_VALUE"""),"LN-10045") -> LN-10045 | B15: =IFERROR(__xludf.DUMMYFUNCTION("""COMPUTED_VALUE"""),131700.0) -> 131700 | C15: =IFERROR(__xludf.DUMMYFUNCTION("""COMPUTED_VALUE"""),129066.0) -> 129066 | D15: =IFERROR(__xludf.DUMMYFUNCTION("""COMPUTED_VALUE"""),2634.0) -> 2634 | E15: =IFERROR(__xludf.DUMMYFUNCTION("""COMPUTED_VALUE"""),0.02) -> 0.02 | F15: =IFERROR(__xludf.DUMMYFUNCTION("""COMPUTED_VALUE"""),21296.0) -> 21296 | G15: =IFERROR(__xludf.DUMMYFUNCTION("""COMPUTED_VALUE"""),21296.0) -> 21296 | H15: =IFERROR(__xludf.DUMMYFUNCTION("""COMPUTED_VALUE"""),0.0) -> 0 | I15: =IFERROR(__xludf.DUMMYFUNCTION("""COMPUTED_VALUE"""),"EXCEPTION") -> EXCEPTION | K15: =IFS(J15="Prepayment", "Update schedule, recalculate interest",J15="System Error", "Escalate to tech team",J15="Waiver Applied", "Verify approval, update ledger",J15="Partial Payment", "Contact customer for balance",J15="Rate Change", "Update loan agreement",J15="", "" ) | L15: =VLOOKUP(A15,LMS_Loan_Tape!A:Z,7,FALSE) -> Piramal | M15: =D15+H15 -> 2634 | N15: =VLOOKUP(A15,LMS_Loan_Tape!A:Z,6,FALSE) -> Home Loan | O15: =VLOOKUP(A15, LMS_Loan_Tape!A14:Z1013,11,false) -> 11
A16: =IFERROR(__xludf.DUMMYFUNCTION("""COMPUTED_VALUE"""),"LN-10048") -> LN-10048 | B16: =IFERROR(__xludf.DUMMYFUNCTION("""COMPUTED_VALUE"""),22297.0) -> 22297 | C16: =IFERROR(__xludf.DUMMYFUNCTION("""COMPUTED_VALUE"""),22297.0) -> 22297 | D16: =IFERROR(__xludf.DUMMYFUNCTION("""COMPUTED_VALUE"""),0.0) -> 0 | E16: =IFERROR(__xludf.DUMMYFUNCTION("""COMPUTED_VALUE"""),0.0) -> 0 | F16: =IFERROR(__xludf.DUMMYFUNCTION("""COMPUTED_VALUE"""),2929.0) -> 2929 | G16: =IFERROR(__xludf.DUMMYFUNCTION("""COMPUTED_VALUE"""),2899.0) -> 2899 | H16: =IFERROR(__xludf.DUMMYFUNCTION("""COMPUTED_VALUE"""),30.0) -> 30 | I16: =IFERROR(__xludf.DUMMYFUNCTION("""COMPUTED_VALUE"""),"EXCEPTION") -> EXCEPTION | K16: =IFS(J16="Prepayment", "Update schedule, recalculate interest",J16="System Error", "Escalate to tech team",J16="Waiver Applied", "Verify approval, update ledger",J16="Partial Payment", "Contact customer for balance",J16="Rate Change", "Update loan agreement",J16="", "" ) | L16: =VLOOKUP(A16,LMS_Loan_Tape!A:Z,7,FALSE) -> DMI | M16: =D16+H16 -> 30 | N16: =VLOOKUP(A16,LMS_Loan_Tape!A:Z,6,FALSE) -> Personal Loan | O16: =VLOOKUP(A16, LMS_Loan_Tape!A15:Z1014,11,false) -> 6
A17: =IFERROR(__xludf.DUMMYFUNCTION("""COMPUTED_VALUE"""),"LN-10051") -> LN-10051 | B17: =IFERROR(__xludf.DUMMYFUNCTION("""COMPUTED_VALUE"""),82659.0) -> 82659 | C17: =IFERROR(__xludf.DUMMYFUNCTION("""COMPUTED_VALUE"""),82659.0) -> 82659 | D17: =IFERROR(__xludf.DUMMYFUNCTION("""COMPUTED_VALUE"""),0.0) -> 0 | E17: =IFERROR(__xludf.DUMMYFUNCTION("""COMPUTED_VALUE"""),0.0) -> 0 | F17: =IFERROR(__xludf.DUMMYFUNCTION("""COMPUTED_VALUE"""),9574.0) -> 9574 | G17: =IFERROR(__xludf.DUMMYFUNCTION("""COMPUTED_VALUE"""),9478.0) -> 9478 | H17: =IFERROR(__xludf.DUMMYFUNCTION("""COMPUTED_VALUE"""),96.0) -> 96 | I17: =IFERROR(__xludf.DUMMYFUNCTION("""COMPUTED_VALUE"""),"EXCEPTION") -> EXCEPTION | K17: =IFS(J17="Prepayment", "Update schedule, recalculate interest",J17="System Error", "Escalate to tech team",J17="Waiver Applied", "Verify approval, update ledger",J17="Partial Payment", "Contact customer for balance",J17="Rate Change", "Update loan agreement",J17="", "" ) | L17: =VLOOKUP(A17,LMS_Loan_Tape!A:Z,7,FALSE) -> Northern Arc | M17: =D17+H17 -> 96 | N17: =VLOOKUP(A17,LMS_Loan_Tape!A:Z,6,FALSE) -> Home Loan | O17: =VLOOKUP(A17, LMS_Loan_Tape!A16:Z1015,11,false) -> 8
A18: =IFERROR(__xludf.DUMMYFUNCTION("""COMPUTED_VALUE"""),"LN-10056") -> LN-10056 | B18: =IFERROR(__xludf.DUMMYFUNCTION("""COMPUTED_VALUE"""),58280.0) -> 58280 | C18: =IFERROR(__xludf.DUMMYFUNCTION("""COMPUTED_VALUE"""),58280.0) -> 58280 | D18: =IFERROR(__xludf.DUMMYFUNCTION("""COMPUTED_VALUE"""),0.0) -> 0 | E18: =IFERROR(__xludf.DUMMYFUNCTION("""COMPUTED_VALUE"""),0.0) -> 0 | F18: =IFERROR(__xludf.DUMMYFUNCTION("""COMPUTED_VALUE"""),10932.0) -> 10932 | G18: =IFERROR(__xludf.DUMMYFUNCTION("""COMPUTED_VALUE"""),10822.0) -> 10822 | H18: =IFERROR(__xludf.DUMMYFUNCTION("""COMPUTED_VALUE"""),110.0) -> 110 | I18: =IFERROR(__xludf.DUMMYFUNCTION("""COMPUTED_VALUE"""),"EXCEPTION") -> EXCEPTION | K18: =IFS(J18="Prepayment", "Update schedule, recalculate interest",J18="System Error", "Escalate to tech team",J18="Waiver Applied", "Verify approval, update ledger",J18="Partial Payment", "Contact customer for balance",J18="Rate Change", "Update loan agreement",J18="", "" ) | L18: =VLOOKUP(A18,LMS_Loan_Tape!A:Z,7,FALSE) -> Liquiloans | M18: =D18+H18 -> 110 | N18: =VLOOKUP(A18,LMS_Loan_Tape!A:Z,6,FALSE) -> Gold Loan | O18: =VLOOKUP(A18, LMS_Loan_Tape!A17:Z1016,11,false) -> 10
A19: =IFERROR(__xludf.DUMMYFUNCTION("""COMPUTED_VALUE"""),"LN-10062") -> LN-10062 | B19: =IFERROR(__xludf.DUMMYFUNCTION("""COMPUTED_VALUE"""),362648.0) -> 362648 | C19: =IFERROR(__xludf.DUMMYFUNCTION("""COMPUTED_VALUE"""),355395.0) -> 355395 | D19: =IFERROR(__xludf.DUMMYFUNCTION("""COMPUTED_VALUE"""),7253.0) -> 7253 | E19: =IFERROR(__xludf.DUMMYFUNCTION("""COMPUTED_VALUE"""),0.020000110299794843) -> 0.02000011 | F19: =IFERROR(__xludf.DUMMYFUNCTION("""COMPUTED_VALUE"""),43577.0) -> 43577 | G19: =IFERROR(__xludf.DUMMYFUNCTION("""COMPUTED_VALUE"""),43577.0) -> 43577 | H19: =IFERROR(__xludf.DUMMYFUNCTION("""COMPUTED_VALUE"""),0.0) -> 0 | I19: =IFERROR(__xludf.DUMMYFUNCTION("""COMPUTED_VALUE"""),"EXCEPTION") -> EXCEPTION | K19: =IFS(J19="Prepayment", "Update schedule, recalculate interest",J19="System Error", "Escalate to tech team",J19="Waiver Applied", "Verify approval, update ledger",J19="Partial Payment", "Contact customer for balance",J19="Rate Change", "Update loan agreement",J19="", "" ) | L19: =VLOOKUP(A19,LMS_Loan_Tape!A:Z,7,FALSE) -> Liquiloans | M19: =D19+H19 -> 7253 | N19: =VLOOKUP(A19,LMS_Loan_Tape!A:Z,6,FALSE) -> Business Loan | O19: =VLOOKUP(A19, LMS_Loan_Tape!A18:Z1017,11,false) -> 1
A20: =IFERROR(__xludf.DUMMYFUNCTION("""COMPUTED_VALUE"""),"LN-10069") -> LN-10069 | B20: =IFERROR(__xludf.DUMMYFUNCTION("""COMPUTED_VALUE"""),109536.0) -> 109536 | C20: =IFERROR(__xludf.DUMMYFUNCTION("""COMPUTED_VALUE"""),110210.0) -> 110210 | D20: =IFERROR(__xludf.DUMMYFUNCTION("""COMPUTED_VALUE"""),-674.0) -> -674 | E20: =IFERROR(__xludf.DUMMYFUNCTION("""COMPUTED_VALUE"""),-0.006153228162430616) -> -0.0061532282 | F20: =IFERROR(__xludf.DUMMYFUNCTION("""COMPUTED_VALUE"""),25724.0) -> 25724 | G20: =IFERROR(__xludf.DUMMYFUNCTION("""COMPUTED_VALUE"""),25724.0) -> 25724 | H20: =IFERROR(__xludf.DUMMYFUNCTION("""COMPUTED_VALUE"""),0.0) -> 0 | I20: =IFERROR(__xludf.DUMMYFUNCTION("""COMPUTED_VALUE"""),"EXCEPTION") -> EXCEPTION | J20: =IFERROR(__xludf.DUMMYFUNCTION("""COMPUTED_VALUE"""),"System Error") -> System Error | K20: =IFS(J20="Prepayment", "Update schedule, recalculate interest",J20="System Error", "Escalate to tech team",J20="Waiver Applied", "Verify approval, update ledger",J20="Partial Payment", "Contact customer for balance",J20="Rate Change", "Update loan agreement",J20="", "" ) -> Escalate to tech team | L20: =VLOOKUP(A20,LMS_Loan_Tape!A:Z,7,FALSE) -> DMI | M20: =D20+H20 -> -674 | N20: =VLOOKUP(A20,LMS_Loan_Tape!A:Z,6,FALSE) -> Home Loan | O20: =VLOOKUP(A20, LMS_Loan_Tape!A19:Z1018,11,false) -> 7
A21: =IFERROR(__xludf.DUMMYFUNCTION("""COMPUTED_VALUE"""),"LN-10075") -> LN-10075 | B21: =IFERROR(__xludf.DUMMYFUNCTION("""COMPUTED_VALUE"""),88094.0) -> 88094 | C21: =IFERROR(__xludf.DUMMYFUNCTION("""COMPUTED_VALUE"""),92498.0) -> 92498 | D21: =IFERROR(__xludf.DUMMYFUNCTION("""COMPUTED_VALUE"""),-4404.0) -> -4404 | E21: =IFERROR(__xludf.DUMMYFUNCTION("""COMPUTED_VALUE"""),-0.04999205394237973) -> -0.049992054 | F21: =IFERROR(__xludf.DUMMYFUNCTION("""COMPUTED_VALUE"""),24407.0) -> 24407 | G21: =IFERROR(__xludf.DUMMYFUNCTION("""COMPUTED_VALUE"""),24407.0) -> 24407 | H21: =IFERROR(__xludf.DUMMYFUNCTION("""COMPUTED_VALUE"""),0.0) -> 0 | I21: =IFERROR(__xludf.DUMMYFUNCTION("""COMPUTED_VALUE"""),"EXCEPTION") -> EXCEPTION | J21: =IFERROR(__xludf.DUMMYFUNCTION("""COMPUTED_VALUE"""),"Rate Change") -> Rate Change | K21: =IFS(J21="Prepayment", "Update schedule, recalculate interest",J21="System Error", "Escalate to tech team",J21="Waiver Applied", "Verify approval, update ledger",J21="Partial Payment", "Contact customer for balance",J21="Rate Change", "Update loan agreement",J21="", "" ) -> Update loan agreement | L21: =VLOOKUP(A21,LMS_Loan_Tape!A:Z,7,FALSE) -> Tata Capital | M21: =D21+H21 -> -4404 | N21: =VLOOKUP(A21,LMS_Loan_Tape!A:Z,6,FALSE) -> Gold Loan | O21: =VLOOKUP(A21, LMS_Loan_Tape!A20:Z1019,11,false) -> 10
A22: =IFERROR(__xludf.DUMMYFUNCTION("""COMPUTED_VALUE"""),"LN-10076") -> LN-10076 | B22: =IFERROR(__xludf.DUMMYFUNCTION("""COMPUTED_VALUE"""),41646.0) -> 41646 | C22: =IFERROR(__xludf.DUMMYFUNCTION("""COMPUTED_VALUE"""),43728.0) -> 43728 | D22: =IFERROR(__xludf.DUMMYFUNCTION("""COMPUTED_VALUE"""),-2082.0) -> -2082 | E22: =IFERROR(__xludf.DUMMYFUNCTION("""COMPUTED_VALUE"""),-0.04999279642702781) -> -0.049992796 | F22: =IFERROR(__xludf.DUMMYFUNCTION("""COMPUTED_VALUE"""),29276.0) -> 29276 | G22: =IFERROR(__xludf.DUMMYFUNCTION("""COMPUTED_VALUE"""),29276.0) -> 29276 | H22: =IFERROR(__xludf.DUMMYFUNCTION("""COMPUTED_VALUE"""),0.0) -> 0 | I22: =IFERROR(__xludf.DUMMYFUNCTION("""COMPUTED_VALUE"""),"EXCEPTION") -> EXCEPTION | J22: =IFERROR(__xludf.DUMMYFUNCTION("""COMPUTED_VALUE"""),"Rate Change") -> Rate Change | K22: =IFS(J22="Prepayment", "Update schedule, recalculate interest",J22="System Error", "Escalate to tech team",J22="Waiver Applied", "Verify approval, update ledger",J22="Partial Payment", "Contact customer for balance",J22="Rate Change", "Update loan agreement",J22="", "" ) -> Update loan agreement | L22: =VLOOKUP(A22,LMS_Loan_Tape!A:Z,7,FALSE) -> Tata Capital | M22: =D22+H22 -> -2082 | N22: =VLOOKUP(A22,LMS_Loan_Tape!A:Z,6,FALSE) -> Home Loan | O22: =VLOOKUP(A22, LMS_Loan_Tape!A21:Z1020,11,false) -> 2
A23: =IFERROR(__xludf.DUMMYFUNCTION("""COMPUTED_VALUE"""),"LN-10081") -> LN-10081 | B23: =IFERROR(__xludf.DUMMYFUNCTION("""COMPUTED_VALUE"""),291821.0) -> 291821 | C23: =IFERROR(__xludf.DUMMYFUNCTION("""COMPUTED_VALUE"""),291821.0) -> 291821 | D23: =IFERROR(__xludf.DUMMYFUNCTION("""COMPUTED_VALUE"""),0.0) -> 0 | E23: =IFERROR(__xludf.DUMMYFUNCTION("""COMPUTED_VALUE"""),0.0) -> 0 | F23: =IFERROR(__xludf.DUMMYFUNCTION("""COMPUTED_VALUE"""),36865.0) -> 36865 | G23: =IFERROR(__xludf.DUMMYFUNCTION("""COMPUTED_VALUE"""),36496.0) -> 36496 | H23: =IFERROR(__xludf.DUMMYFUNCTION("""COMPUTED_VALUE"""),369.0) -> 369 | I23: =IFERROR(__xludf.DUMMYFUNCTION("""COMPUTED_VALUE"""),"EXCEPTION") -> EXCEPTION | K23: =IFS(J23="Prepayment", "Update schedule, recalculate interest",J23="System Error", "Escalate to tech team",J23="Waiver Applied", "Verify approval, update ledger",J23="Partial Payment", "Contact customer for balance",J23="Rate Change", "Update loan agreement",J23="", "" ) | L23: =VLOOKUP(A23,LMS_Loan_Tape!A:Z,7,FALSE) -> Piramal | M23: =D23+H23 -> 369 | N23: =VLOOKUP(A23,LMS_Loan_Tape!A:Z,6,FALSE) -> Personal Loan | O23: =VLOOKUP(A23, LMS_Loan_Tape!A22:Z1021,11,false) -> 7
A24: =IFERROR(__xludf.DUMMYFUNCTION("""COMPUTED_VALUE"""),"LN-10082") -> LN-10082 | B24: =IFERROR(__xludf.DUMMYFUNCTION("""COMPUTED_VALUE"""),296219.0) -> 296219 | C24: =IFERROR(__xludf.DUMMYFUNCTION("""COMPUTED_VALUE"""),290294.0) -> 290294 | D24: =IFERROR(__xludf.DUMMYFUNCTION("""COMPUTED_VALUE"""),5925.0) -> 5925 | E24: =IFERROR(__xludf.DUMMYFUNCTION("""COMPUTED_VALUE"""),0.02000209304602338) -> 0.020002093 | F24: =IFERROR(__xludf.DUMMYFUNCTION("""COMPUTED_VALUE"""),32049.0) -> 32049 | G24: =IFERROR(__xludf.DUMMYFUNCTION("""COMPUTED_VALUE"""),32049.0) -> 32049 | H24: =IFERROR(__xludf.DUMMYFUNCTION("""COMPUTED_VALUE"""),0.0) -> 0 | I24: =IFERROR(__xludf.DUMMYFUNCTION("""COMPUTED_VALUE"""),"EXCEPTION") -> EXCEPTION | K24: =IFS(J24="Prepayment", "Update schedule, recalculate interest",J24="System Error", "Escalate to tech team",J24="Waiver Applied", "Verify approval, update ledger",J24="Partial Payment", "Contact customer for balance",J24="Rate Change", "Update loan agreement",J24="", "" ) | L24: =VLOOKUP(A24,LMS_Loan_Tape!A:Z,7,FALSE) -> Northern Arc | M24: =D24+H24 -> 5925 | N24: =VLOOKUP(A24,LMS_Loan_Tape!A:Z,6,FALSE) -> Gold Loan | O24: =VLOOKUP(A24, LMS_Loan_Tape!A23:Z1022,11,false) -> 7
A25: =IFERROR(__xludf.DUMMYFUNCTION("""COMPUTED_VALUE"""),"LN-10085") -> LN-10085 | B25: =IFERROR(__xludf.DUMMYFUNCTION("""COMPUTED_VALUE"""),112602.0) -> 112602 | C25: =IFERROR(__xludf.DUMMYFUNCTION("""COMPUTED_VALUE"""),67561.0) -> 67561 | D25: =IFERROR(__xludf.DUMMYFUNCTION("""COMPUTED_VALUE"""),45041.0) -> 45041 | E25: =IFERROR(__xludf.DUMMYFUNCTION("""COMPUTED_VALUE"""),0.400001776167386) -> 0.40000178 | F25: =IFERROR(__xludf.DUMMYFUNCTION("""COMPUTED_VALUE"""),13350.0) -> 13350 | G25: =IFERROR(__xludf.DUMMYFUNCTION("""COMPUTED_VALUE"""),13350.0) -> 13350 | H25: =IFERROR(__xludf.DUMMYFUNCTION("""COMPUTED_VALUE"""),0.0) -> 0 | I25: =IFERROR(__xludf.DUMMYFUNCTION("""COMPUTED_VALUE"""),"EXCEPTION") -> EXCEPTION | J25: =IFERROR(__xludf.DUMMYFUNCTION("""COMPUTED_VALUE"""),"Partial Payment") -> Partial Payment | K25: =IFS(J25="Prepayment", "Update schedule, recalculate interest",J25="System Error", "Escalate to tech team",J25="Waiver Applied", "Verify approval, update ledger",J25="Partial Payment", "Contact customer for balance",J25="Rate Change", "Update loan agreement",J25="", "" ) -> Contact customer for balance | L25: =VLOOKUP(A25,LMS_Loan_Tape!A:Z,7,FALSE) -> Piramal | M25: =D25+H25 -> 45041 | N25: =VLOOKUP(A25,LMS_Loan_Tape!A:Z,6,FALSE) -> Business Loan | O25: =VLOOKUP(A25, LMS_Loan_Tape!A24:Z1023,11,false) -> 9
A26: =IFERROR(__xludf.DUMMYFUNCTION("""COMPUTED_VALUE"""),"LN-10087") -> LN-10087 | B26: =IFERROR(__xludf.DUMMYFUNCTION("""COMPUTED_VALUE"""),53344.0) -> 53344 | C26: =IFERROR(__xludf.DUMMYFUNCTION("""COMPUTED_VALUE"""),32006.0) -> 32006 | D26: =IFERROR(__xludf.DUMMYFUNCTION("""COMPUTED_VALUE"""),21338.0) -> 21338 | E26: =IFERROR(__xludf.DUMMYFUNCTION("""COMPUTED_VALUE"""),0.40000749850029993) -> 0.4000075 | F26: =IFERROR(__xludf.DUMMYFUNCTION("""COMPUTED_VALUE"""),10168.0) -> 10168 | G26: =IFERROR(__xludf.DUMMYFUNCTION("""COMPUTED_VALUE"""),10168.0) -> 10168 | H26: =IFERROR(__xludf.DUMMYFUNCTION("""COMPUTED_VALUE"""),0.0) -> 0 | I26: =IFERROR(__xludf.DUMMYFUNCTION("""COMPUTED_VALUE"""),"EXCEPTION") -> EXCEPTION | J26: =IFERROR(__xludf.DUMMYFUNCTION("""COMPUTED_VALUE"""),"Partial Payment") -> Partial Payment | K26: =IFS(J26="Prepayment", "Update schedule, recalculate interest",J26="System Error", "Escalate to tech team",J26="Waiver Applied", "Verify approval, update ledger",J26="Partial Payment", "Contact customer for balance",J26="Rate Change", "Update loan agreement",J26="", "" ) -> Contact customer for balance | L26: =VLOOKUP(A26,LMS_Loan_Tape!A:Z,7,FALSE) -> Northern Arc | M26: =D26+H26 -> 21338 | N26: =VLOOKUP(A26,LMS_Loan_Tape!A:Z,6,FALSE) -> Gold Loan | O26: =VLOOKUP(A26, LMS_Loan_Tape!A25:Z1024,11,false) -> 9
A27: =IFERROR(__xludf.DUMMYFUNCTION("""COMPUTED_VALUE"""),"LN-10091") -> LN-10091 | B27: =IFERROR(__xludf.DUMMYFUNCTION("""COMPUTED_VALUE"""),30963.0) -> 30963 | C27: =IFERROR(__xludf.DUMMYFUNCTION("""COMPUTED_VALUE"""),30343.0) -> 30343 | D27: =IFERROR(__xludf.DUMMYFUNCTION("""COMPUTED_VALUE"""),620.0) -> 620 | E27: =IFERROR(__xludf.DUMMYFUNCTION("""COMPUTED_VALUE"""),0.02002389949294319) -> 0.020023899 | F27: =IFERROR(__xludf.DUMMYFUNCTION("""COMPUTED_VALUE"""),23097.0) -> 23097 | G27: =IFERROR(__xludf.DUMMYFUNCTION("""COMPUTED_VALUE"""),23097.0) -> 23097 | H27: =IFERROR(__xludf.DUMMYFUNCTION("""COMPUTED_VALUE"""),0.0) -> 0 | I27: =IFERROR(__xludf.DUMMYFUNCTION("""COMPUTED_VALUE"""),"EXCEPTION") -> EXCEPTION | K27: =IFS(J27="Prepayment", "Update schedule, recalculate interest",J27="System Error", "Escalate to tech team",J27="Waiver Applied", "Verify approval, update ledger",J27="Partial Payment", "Contact customer for balance",J27="Rate Change", "Update loan agreement",J27="", "" ) | L27: =VLOOKUP(A27,LMS_Loan_Tape!A:Z,7,FALSE) -> DMI | M27: =D27+H27 -> 620 | N27: =VLOOKUP(A27,LMS_Loan_Tape!A:Z,6,FALSE) -> Home Loan | O27: =VLOOKUP(A27, LMS_Loan_Tape!A26:Z1025,11,false) -> 3
A28: =IFERROR(__xludf.DUMMYFUNCTION("""COMPUTED_VALUE"""),"LN-10093") -> LN-10093 | B28: =IFERROR(__xludf.DUMMYFUNCTION("""COMPUTED_VALUE"""),43894.0) -> 43894 | C28: =IFERROR(__xludf.DUMMYFUNCTION("""COMPUTED_VALUE"""),35115.0) -> 35115 | D28: =IFERROR(__xludf.DUMMYFUNCTION("""COMPUTED_VALUE"""),8779.0) -> 8779 | E28: =IFERROR(__xludf.DUMMYFUNCTION("""COMPUTED_VALUE"""),0.2000045564314029) -> 0.20000456 | F28: =IFERROR(__xludf.DUMMYFUNCTION("""COMPUTED_VALUE"""),53579.0) -> 53579 | G28: =IFERROR(__xludf.DUMMYFUNCTION("""COMPUTED_VALUE"""),53579.0) -> 53579 | H28: =IFERROR(__xludf.DUMMYFUNCTION("""COMPUTED_VALUE"""),0.0) -> 0 | I28: =IFERROR(__xludf.DUMMYFUNCTION("""COMPUTED_VALUE"""),"EXCEPTION") -> EXCEPTION | J28: =IFERROR(__xludf.DUMMYFUNCTION("""COMPUTED_VALUE"""),"Prepayment") -> Prepayment | K28: =IFS(J28="Prepayment", "Update schedule, recalculate interest",J28="System Error", "Escalate to tech team",J28="Waiver Applied", "Verify approval, update ledger",J28="Partial Payment", "Contact customer for balance",J28="Rate Change", "Update loan agreement",J28="", "" ) -> Update schedule, recalculate interest | L28: =VLOOKUP(A28,LMS_Loan_Tape!A:Z,7,FALSE) -> Tata Capital | M28: =D28+H28 -> 8779 | N28: =VLOOKUP(A28,LMS_Loan_Tape!A:Z,6,FALSE) -> Gold Loan | O28: =VLOOKUP(A28, LMS_Loan_Tape!A27:Z1026,11,false) -> 3
A29: =IFERROR(__xludf.DUMMYFUNCTION("""COMPUTED_VALUE"""),"LN-10097") -> LN-10097 | B29: =IFERROR(__xludf.DUMMYFUNCTION("""COMPUTED_VALUE"""),286683.0) -> 286683 | C29: =IFERROR(__xludf.DUMMYFUNCTION("""COMPUTED_VALUE"""),286683.0) -> 286683 | D29: =IFERROR(__xludf.DUMMYFUNCTION("""COMPUTED_VALUE"""),0.0) -> 0 | E29: =IFERROR(__xludf.DUMMYFUNCTION("""COMPUTED_VALUE"""),0.0) -> 0 | F29: =IFERROR(__xludf.DUMMYFUNCTION("""COMPUTED_VALUE"""),45617.0) -> 45617 | G29: =IFERROR(__xludf.DUMMYFUNCTION("""COMPUTED_VALUE"""),45160.0) -> 45160 | H29: =IFERROR(__xludf.DUMMYFUNCTION("""COMPUTED_VALUE"""),457.0) -> 457 | I29: =IFERROR(__xludf.DUMMYFUNCTION("""COMPUTED_VALUE"""),"EXCEPTION") -> EXCEPTION | K29: =IFS(J29="Prepayment", "Update schedule, recalculate interest",J29="System Error", "Escalate to tech team",J29="Waiver Applied", "Verify approval, update ledger",J29="Partial Payment", "Contact customer for balance",J29="Rate Change", "Update loan agreement",J29="", "" ) | L29: =VLOOKUP(A29,LMS_Loan_Tape!A:Z,7,FALSE) -> Liquiloans | M29: =D29+H29 -> 457 | N29: =VLOOKUP(A29,LMS_Loan_Tape!A:Z,6,FALSE) -> Home Loan | O29: =VLOOKUP(A29, LMS_Loan_Tape!A28:Z1027,11,false) -> 8
A30: =IFERROR(__xludf.DUMMYFUNCTION("""COMPUTED_VALUE"""),"LN-10098") -> LN-10098 | B30: =IFERROR(__xludf.DUMMYFUNCTION("""COMPUTED_VALUE"""),188079.0) -> 188079 | C30: =IFERROR(__xludf.DUMMYFUNCTION("""COMPUTED_VALUE"""),188079.0) -> 188079 | D30: =IFERROR(__xludf.DUMMYFUNCTION("""COMPUTED_VALUE"""),0.0) -> 0 | E30: =IFERROR(__xludf.DUMMYFUNCTION("""COMPUTED_VALUE"""),0.0) -> 0 | F30: =IFERROR(__xludf.DUMMYFUNCTION("""COMPUTED_VALUE"""),18362.0) -> 18362 | G30: =IFERROR(__xludf.DUMMYFUNCTION("""COMPUTED_VALUE"""),18178.0) -> 18178 | H30: =IFERROR(__xludf.DUMMYFUNCTION("""COMPUTED_VALUE"""),184.0) -> 184 | I30: =IFERROR(__xludf.DUMMYFUNCTION("""COMPUTED_VALUE"""),"EXCEPTION") -> EXCEPTION | K30: =IFS(J30="Prepayment", "Update schedule, recalculate interest",J30="System Error", "Escalate to tech team",J30="Waiver Applied", "Verify approval, update ledger",J30="Partial Payment", "Contact customer for balance",J30="Rate Change", "Update loan agreement",J30="", "" ) | L30: =VLOOKUP(A30,LMS_Loan_Tape!A:Z,7,FALSE) -> Liquiloans | M30: =D30+H30 -> 184 | N30: =VLOOKUP(A30,LMS_Loan_Tape!A:Z,6,FALSE) -> Home Loan | O30: =VLOOKUP(A30, LMS_Loan_Tape!A29:Z1028,11,false) -> 6
A31: =IFERROR(__xludf.DUMMYFUNCTION("""COMPUTED_VALUE"""),"LN-10102") -> LN-10102 | B31: =IFERROR(__xludf.DUMMYFUNCTION("""COMPUTED_VALUE"""),333909.0) -> 333909 | C31: =IFERROR(__xludf.DUMMYFUNCTION("""COMPUTED_VALUE"""),300518.0) -> 300518 | D31: =IFERROR(__xludf.DUMMYFUNCTION("""COMPUTED_VALUE"""),33391.0) -> 33391 | E31: =IFERROR(__xludf.DUMMYFUNCTION("""COMPUTED_VALUE"""),0.10000029948279322) -> 0.1000003 | F31: =IFERROR(__xludf.DUMMYFUNCTION("""COMPUTED_VALUE"""),41478.0) -> 41478 | G31: =IFERROR(__xludf.DUMMYFUNCTION("""COMPUTED_VALUE"""),20739.0) -> 20739 | H31: =IFERROR(__xludf.DUMMYFUNCTION("""COMPUTED_VALUE"""),20739.0) -> 20739 | I31: =IFERROR(__xludf.DUMMYFUNCTION("""COMPUTED_VALUE"""),"EXCEPTION") -> EXCEPTION | J31: =IFERROR(__xludf.DUMMYFUNCTION("""COMPUTED_VALUE"""),"Waiver Applied") -> Waiver Applied | K31: =IFS(J31="Prepayment", "Update schedule, recalculate interest",J31="System Error", "Escalate to tech team",J31="Waiver Applied", "Verify approval, update ledger",J31="Partial Payment", "Contact customer for balance",J31="Rate Change", "Update loan agreement",J31="", "" ) -> Verify approval, update ledger | L31: =VLOOKUP(A31,LMS_Loan_Tape!A:Z,7,FALSE) -> DMI | M31: =D31+H31 -> 54130 | N31: =VLOOKUP(A31,LMS_Loan_Tape!A:Z,6,FALSE) -> Home Loan | O31: =VLOOKUP(A31, LMS_Loan_Tape!A30:Z1029,11,false) -> 8
A32: =IFERROR(__xludf.DUMMYFUNCTION("""COMPUTED_VALUE"""),"LN-10105") -> LN-10105 | B32: =IFERROR(__xludf.DUMMYFUNCTION("""COMPUTED_VALUE"""),78377.0) -> 78377 | C32: =IFERROR(__xludf.DUMMYFUNCTION("""COMPUTED_VALUE"""),70539.0) -> 70539 | D32: =IFERROR(__xludf.DUMMYFUNCTION("""COMPUTED_VALUE"""),7838.0) -> 7838 | E32: =IFERROR(__xludf.DUMMYFUNCTION("""COMPUTED_VALUE"""),0.1000038276535208) -> 0.10000383 | F32: =IFERROR(__xludf.DUMMYFUNCTION("""COMPUTED_VALUE"""),20750.0) -> 20750 | G32: =IFERROR(__xludf.DUMMYFUNCTION("""COMPUTED_VALUE"""),10375.0) -> 10375 | H32: =IFERROR(__xludf.DUMMYFUNCTION("""COMPUTED_VALUE"""),10375.0) -> 10375 | I32: =IFERROR(__xludf.DUMMYFUNCTION("""COMPUTED_VALUE"""),"EXCEPTION") -> EXCEPTION | J32: =IFERROR(__xludf.DUMMYFUNCTION("""COMPUTED_VALUE"""),"Waiver Applied") -> Waiver Applied | K32: =IFS(J32="Prepayment", "Update schedule, recalculate interest",J32="System Error", "Escalate to tech team",J32="Waiver Applied", "Verify approval, update ledger",J32="Partial Payment", "Contact customer for balance",J32="Rate Change", "Update loan agreement",J32="", "" ) -> Verify approval, update ledger | L32: =VLOOKUP(A32,LMS_Loan_Tape!A:Z,7,FALSE) -> Liquiloans | M32: =D32+H32 -> 18213 | N32: =VLOOKUP(A32,LMS_Loan_Tape!A:Z,6,FALSE) -> Gold Loan | O32: =VLOOKUP(A32, LMS_Loan_Tape!A31:Z1030,11,false) -> 8
A33: =IFERROR(__xludf.DUMMYFUNCTION("""COMPUTED_VALUE"""),"LN-10110") -> LN-10110 | B33: =IFERROR(__xludf.DUMMYFUNCTION("""COMPUTED_VALUE"""),105195.0) -> 105195 | C33: =IFERROR(__xludf.DUMMYFUNCTION("""COMPUTED_VALUE"""),105791.0) -> 105791 | D33: =IFERROR(__xludf.DUMMYFUNCTION("""COMPUTED_VALUE"""),-596.0) -> -596 | E33: =IFERROR(__xludf.DUMMYFUNCTION("""COMPUTED_VALUE"""),-0.0056656685203669375) -> -0.0056656685 | F33: =IFERROR(__xludf.DUMMYFUNCTION("""COMPUTED_VALUE"""),31570.0) -> 31570 | G33: =IFERROR(__xludf.DUMMYFUNCTION("""COMPUTED_VALUE"""),31570.0) -> 31570 | H33: =IFERROR(__xludf.DUMMYFUNCTION("""COMPUTED_VALUE"""),0.0) -> 0 | I33: =IFERROR(__xludf.DUMMYFUNCTION("""COMPUTED_VALUE"""),"EXCEPTION") -> EXCEPTION | J33: =IFERROR(__xludf.DUMMYFUNCTION("""COMPUTED_VALUE"""),"System Error") -> System Error | K33: =IFS(J33="Prepayment", "Update schedule, recalculate interest",J33="System Error", "Escalate to tech team",J33="Waiver Applied", "Verify approval, update ledger",J33="Partial Payment", "Contact customer for balance",J33="Rate Change", "Update loan agreement",J33="", "" ) -> Escalate to tech team | L33: =VLOOKUP(A33,LMS_Loan_Tape!A:Z,7,FALSE) -> Tata Capital | M33: =D33+H33 -> -596 | N33: =VLOOKUP(A33,LMS_Loan_Tape!A:Z,6,FALSE) -> Home Loan | O33: =VLOOKUP(A33, LMS_Loan_Tape!A32:Z1031,11,false) -> 12
A34: =IFERROR(__xludf.DUMMYFUNCTION("""COMPUTED_VALUE"""),"LN-10118") -> LN-10118 | B34: =IFERROR(__xludf.DUMMYFUNCTION("""COMPUTED_VALUE"""),11813.0) -> 11813 | C34: =IFERROR(__xludf.DUMMYFUNCTION("""COMPUTED_VALUE"""),10631.0) -> 10631 | D34: =IFERROR(__xludf.DUMMYFUNCTION("""COMPUTED_VALUE"""),1182.0) -> 1182 | E34: =IFERROR(__xludf.DUMMYFUNCTION("""COMPUTED_VALUE"""),0.100059256751037) -> 0.10005926 | F34: =IFERROR(__xludf.DUMMYFUNCTION("""COMPUTED_VALUE"""),12323.0) -> 12323 | G34: =IFERROR(__xludf.DUMMYFUNCTION("""COMPUTED_VALUE"""),6161.0) -> 6161 | H34: =IFERROR(__xludf.DUMMYFUNCTION("""COMPUTED_VALUE"""),6162.0) -> 6162 | I34: =IFERROR(__xludf.DUMMYFUNCTION("""COMPUTED_VALUE"""),"EXCEPTION") -> EXCEPTION | J34: =IFERROR(__xludf.DUMMYFUNCTION("""COMPUTED_VALUE"""),"Waiver Applied") -> Waiver Applied | K34: =IFS(J34="Prepayment", "Update schedule, recalculate interest",J34="System Error", "Escalate to tech team",J34="Waiver Applied", "Verify approval, update ledger",J34="Partial Payment", "Contact customer for balance",J34="Rate Change", "Update loan agreement",J34="", "" ) -> Verify approval, update ledger | L34: =VLOOKUP(A34,LMS_Loan_Tape!A:Z,7,FALSE) -> Tata Capital | M34: =D34+H34 -> 7344 | N34: =VLOOKUP(A34,LMS_Loan_Tape!A:Z,6,FALSE) -> Business Loan | O34: =VLOOKUP(A34, LMS_Loan_Tape!A33:Z1032,11,false) -> 4
A35: =IFERROR(__xludf.DUMMYFUNCTION("""COMPUTED_VALUE"""),"LN-10125") -> LN-10125 | B35: =IFERROR(__xludf.DUMMYFUNCTION("""COMPUTED_VALUE"""),396217.0) -> 396217 | C35: =IFERROR(__xludf.DUMMYFUNCTION("""COMPUTED_VALUE"""),396217.0) -> 396217 | D35: =IFERROR(__xludf.DUMMYFUNCTION("""COMPUTED_VALUE"""),0.0) -> 0 | E35: =IFERROR(__xludf.DUMMYFUNCTION("""COMPUTED_VALUE"""),0.0) -> 0 | F35: =IFERROR(__xludf.DUMMYFUNCTION("""COMPUTED_VALUE"""),27455.0) -> 27455 | G35: =IFERROR(__xludf.DUMMYFUNCTION("""COMPUTED_VALUE"""),27180.0) -> 27180 | H35: =IFERROR(__xludf.DUMMYFUNCTION("""COMPUTED_VALUE"""),275.0) -> 275 | I35: =IFERROR(__xludf.DUMMYFUNCTION("""COMPUTED_VALUE"""),"EXCEPTION") -> EXCEPTION | K35: =IFS(J35="Prepayment", "Update schedule, recalculate interest",J35="System Error", "Escalate to tech team",J35="Waiver Applied", "Verify approval, update ledger",J35="Partial Payment", "Contact customer for balance",J35="Rate Change", "Update loan agreement",J35="", "" ) | L35: =VLOOKUP(A35,LMS_Loan_Tape!A:Z,7,FALSE) -> Tata Capital | M35: =D35+H35 -> 275 | N35: =VLOOKUP(A35,LMS_Loan_Tape!A:Z,6,FALSE) -> Personal Loan | O35: =VLOOKUP(A35, LMS_Loan_Tape!A34:Z1033,11,false) -> 1
A36: =IFERROR(__xludf.DUMMYFUNCTION("""COMPUTED_VALUE"""),"LN-10127") -> LN-10127 | B36: =IFERROR(__xludf.DUMMYFUNCTION("""COMPUTED_VALUE"""),140015.0) -> 140015 | C36: =IFERROR(__xludf.DUMMYFUNCTION("""COMPUTED_VALUE"""),137214.0) -> 137214 | D36: =IFERROR(__xludf.DUMMYFUNCTION("""COMPUTED_VALUE"""),2801.0) -> 2801 | E36: =IFERROR(__xludf.DUMMYFUNCTION("""COMPUTED_VALUE"""),0.020004999464343105) -> 0.020004999 | F36: =IFERROR(__xludf.DUMMYFUNCTION("""COMPUTED_VALUE"""),17164.0) -> 17164 | G36: =IFERROR(__xludf.DUMMYFUNCTION("""COMPUTED_VALUE"""),17164.0) -> 17164 | H36: =IFERROR(__xludf.DUMMYFUNCTION("""COMPUTED_VALUE"""),0.0) -> 0 | I36: =IFERROR(__xludf.DUMMYFUNCTION("""COMPUTED_VALUE"""),"EXCEPTION") -> EXCEPTION | K36: =IFS(J36="Prepayment", "Update schedule, recalculate interest",J36="System Error", "Escalate to tech team",J36="Waiver Applied", "Verify approval, update ledger",J36="Partial Payment", "Contact customer for balance",J36="Rate Change", "Update loan agreement",J36="", "" ) | L36: =VLOOKUP(A36,LMS_Loan_Tape!A:Z,7,FALSE) -> Piramal | M36: =D36+H36 -> 2801 | N36: =VLOOKUP(A36,LMS_Loan_Tape!A:Z,6,FALSE) -> Gold Loan | O36: =VLOOKUP(A36, LMS_Loan_Tape!A35:Z1034,11,false) -> 4
A37: =IFERROR(__xludf.DUMMYFUNCTION("""COMPUTED_VALUE"""),"LN-10131") -> LN-10131 | B37: =IFERROR(__xludf.DUMMYFUNCTION("""COMPUTED_VALUE"""),310973.0) -> 310973 | C37: =IFERROR(__xludf.DUMMYFUNCTION("""COMPUTED_VALUE"""),326521.0) -> 326521 | D37: =IFERROR(__xludf.DUMMYFUNCTION("""COMPUTED_VALUE"""),-15548.0) -> -15548 | E37: =IFERROR(__xludf.DUMMYFUNCTION("""COMPUTED_VALUE"""),-0.04999790978638017) -> -0.04999791 | F37: =IFERROR(__xludf.DUMMYFUNCTION("""COMPUTED_VALUE"""),38472.0) -> 38472 | G37: =IFERROR(__xludf.DUMMYFUNCTION("""COMPUTED_VALUE"""),38472.0) -> 38472 | H37: =IFERROR(__xludf.DUMMYFUNCTION("""COMPUTED_VALUE"""),0.0) -> 0 | I37: =IFERROR(__xludf.DUMMYFUNCTION("""COMPUTED_VALUE"""),"EXCEPTION") -> EXCEPTION | J37: =IFERROR(__xludf.DUMMYFUNCTION("""COMPUTED_VALUE"""),"Rate Change") -> Rate Change | K37: =IFS(J37="Prepayment", "Update schedule, recalculate interest",J37="System Error", "Escalate to tech team",J37="Waiver Applied", "Verify approval, update ledger",J37="Partial Payment", "Contact customer for balance",J37="Rate Change", "Update loan agreement",J37="", "" ) -> Update loan agreement | L37: =VLOOKUP(A37,LMS_Loan_Tape!A:Z,7,FALSE) -> DMI | M37: =D37+H37 -> -15548 | N37: =VLOOKUP(A37,LMS_Loan_Tape!A:Z,6,FALSE) -> Home Loan | O37: =VLOOKUP(A37, LMS_Loan_Tape!A36:Z1035,11,false) -> 8
